Workbook
Name K: {#N/A,#N/A,FALSE,"FRANCE MONTH DETAIL FFR";#N/A,#N/A,FALSE,"FRANCE MONTH DETAIL NLG";#N/A,#N/A,FALSE,"FRANCE YTD DETAIL FFR";#N/A,#N/A,FALSE,"FRANCE YTD DETAIL NLG"}
Name J: #N/A
Name Q: #N/A
Name B: [40]Competitors!$S$26:$Z$44
Name \0: [3]Competitors!$A$12:$A$22
Name \A: #REF!
Name \B: #REF!
Name \C: #REF!
Name \L: #REF!
Name \M: #REF!
Name \p: '[2]AU Zone'!$U$2
Name \R: #REF!
Name \S: #REF!
Name \W: #REF!
Name \Z: #REF!
Name _?: #REF!
Name _??????: #REF!
Name __?: #REF!
Name __??????: #REF!
Name ________________123Graph_ACHART_3: [4]Competitors!$E$5:$E$10
Name ______________123Graph_ACHART_3: [4]Competitors!$E$5:$E$10
Name _____________Key1: #N/A
Name _____________Key2: #N/A
Name ____________AFF2: #N/A
Name ____________Key1: #REF!
Name ____________Key2: #REF!
Name ___________AFF1: #REF!
Name ___________AFF2: #REF!
Name ___________Key1: #REF!
Name ___________Key2: #REF!
Name ___________UPD1: #REF!
Name ___________UPD2: #REF!
Name __________AFF2: #REF!
Name __________Key1: #REF!
Name __________Key2: #REF!
Name _________AFF1: #REF!
Name _________AFF2: #REF!
Name _________Key1: #REF!
Name _________Key2: #REF!
Name _________UPD1: #REF!
Name _________UPD2: #REF!
Name ________123Graph_ACHART_3: #N/A
Name ________123Graph_CCHART_3: [5]Competitors!$I$5:$I$10
Name ________123Graph_DCHART_3: #N/A
Name ________123Graph_DCHART_4: [5]Competitors!$K$12:$K$22
Name ________AFF1: #REF!
Name ________AFF2: #REF!
Name ________Key1: #REF!
Name ________Key2: #REF!
Name ________UPD1: #REF!
Name ________UPD2: #REF!
Name _______123Graph_ACHART_3: [5]Competitors!$E$5:$E$10
Name _______123Graph_ACHART_4: #N/A
Name _______123Graph_BCHART_3: #N/A
Name _______123Graph_BCHART_4: #N/A
Name _______123Graph_CCHART_3: #N/A
Name _______123Graph_CCHART_4: #N/A
Name _______123Graph_DCHART_3: [7]Competitors!$K$5:$K$10
Name _______123Graph_DCHART_4: #N/A
Name _______123Graph_ECHART_3: #N/A

Sheet 明细
A1: File Name | B1: SKU Name | C1: Additional Data | D1: 箱数 | E1: FBA Warehouse | G1: 单箱数量 | H1: 总数 | I1: 单个净重 | J1: 总净重 | K1: 包装盒重量 | L1: 箱子重量 | M1: 单箱重量 | N1: 总毛重 | O1: 单价 | P1: 体积 | R1: 长 | S1: 宽 | T1: 高 | U1: 商品统称 | V1: HS | W1: 目的地 | X1: 英文目的地 | Y1: 仓库地址全 | Z1: 申报要素 | AA1: 境内货源地 | AB1: 起运港 | AC1: 离境口岸 | AD1: 申报单位 | AE1: 法定单位 | AF1: 国家编码 | AG1: 货币编码
G2: {=IFERROR(INDEX(商品管理!J:J,MATCH(B2,商品管理!A:A,0)),"")} | H2: {=D2*G2+IFERROR(VALUE(INDEX(#REF!,MATCH(B2,#REF!,0))),0)} -> #VALUE! | I2: {=IFERROR(INDEX(商品管理!K:K,MATCH(B2,商品管理!A:A,0)),"")} | J2: =H2*I2 -> #VALUE! | K2: {=IFERROR(INDEX(商品管理!L:L,MATCH(B2,商品管理!A:A,0)),"")} | L2: 1.5 | M2: =I2*G2+L2+G2*K2 -> #VALUE! | N2: =J2+D2*1.6+G2*D2*K2 -> #VALUE! | O2: {=IFERROR(INDEX(商品管理!P:P,MATCH(B2,商品管理!A:A,0)),"")} | P2: =R2*S2*T2*D2/1000000 -> #VALUE! | R2: {=IFERROR(INDEX(商品管理!Q:Q,MATCH(B2,商品管理!A:A,0)),"")} | S2: {=IFERROR(INDEX(商品管理!R:R,MATCH(B2,商品管理!A:A,0)),"")} | T2: {=IFERROR(INDEX(商品管理!S:S,MATCH(B2,商品管理!A:A,0)),"")} | U2: {=IFERROR(INDEX(商品管理!B:B,MATCH(B2,商品管理!A:A,0)),"")} | V2: {=IFERROR(INDEX(商品管理!C:C,MATCH(B2,商品管理!A:A,0)),"")} | Y2: {=IFERROR(INDEX(FBA仓库代码表!F:F,MATCH(E2,FBA仓库代码表!B:B,0)),"")} | Z2: {="申报要素："&IFERROR(INDEX(商品管理!D:D,MATCH(B2,商品管理!A:A,0)),"")} -> 申报要素： | AA2: 广东东莞 | AD2: {=IFERROR(INDEX(商品管理!E:E,MATCH(B2,商品管理!A:A,0)),"")} | AE2: {=IFERROR(INDEX(商品管理!F:F,MATCH(B2,商品管理!A:A,0)),"")} | AF2: {=IFERROR(INDEX(FBA仓库代码表!G:G,MATCH(E2,FBA仓库代码表!B:B,0)),"")} | AG2: {=IFERROR(INDEX(FBA仓库代码表!H:H,MATCH(E2,FBA仓库代码表!B:B,0)),"")}
AD142: {=IFERROR(INDEX(商品管理!E:E,MATCH(B142,商品管理!A:A,0)),"")} | AE142: {=IFERROR(INDEX(商品管理!F:F,MATCH(B142,商品管理!A:A,0)),"")} | AF142: {=IFERROR(INDEX(FBA仓库代码表!G:G,MATCH(E142,FBA仓库代码表!B:B,0)),"")} | AG142: {=IFERROR(INDEX(FBA仓库代码表!H:H,MATCH(E142,FBA仓库代码表!B:B,0)),"")}
AD143: {=IFERROR(INDEX(商品管理!E:E,MATCH(B143,商品管理!A:A,0)),"")} | AE143: {=IFERROR(INDEX(商品管理!F:F,MATCH(B143,商品管理!A:A,0)),"")} | AF143: {=IFERROR(INDEX(FBA仓库代码表!G:G,MATCH(E143,FBA仓库代码表!B:B,0)),"")} | AG143: {=IFERROR(INDEX(FBA仓库代码表!H:H,MATCH(E143,FBA仓库代码表!B:B,0)),"")}
AD144: {=IFERROR(INDEX(商品管理!E:E,MATCH(B144,商品管理!A:A,0)),"")} | AE144: {=IFERROR(INDEX(商品管理!F:F,MATCH(B144,商品管理!A:A,0)),"")} | AF144: {=IFERROR(INDEX(FBA仓库代码表!G:G,MATCH(E144,FBA仓库代码表!B:B,0)),"")} | AG144: {=IFERROR(INDEX(FBA仓库代码表!H:H,MATCH(E144,FBA仓库代码表!B:B,0)),"")}
AD145: {=IFERROR(INDEX(商品管理!E:E,MATCH(B145,商品管理!A:A,0)),"")} | AE145: {=IFERROR(INDEX(商品管理!F:F,MATCH(B145,商品管理!A:A,0)),"")} | AF145: {=IFERROR(INDEX(FBA仓库代码表!G:G,MATCH(E145,FBA仓库代码表!B:B,0)),"")} | AG145: {=IFERROR(INDEX(FBA仓库代码表!H:H,MATCH(E145,FBA仓库代码表!B:B,0)),"")}
AD146: {=IFERROR(INDEX(商品管理!E:E,MATCH(B146,商品管理!A:A,0)),"")} | AE146: {=IFERROR(INDEX(商品管理!F:F,MATCH(B146,商品管理!A:A,0)),"")} | AF146: {=IFERROR(INDEX(FBA仓库代码表!G:G,MATCH(E146,FBA仓库代码表!B:B,0)),"")} | AG146: {=IFERROR(INDEX(FBA仓库代码表!H:H,MATCH(E146,FBA仓库代码表!B:B,0)),"")}
AD147: {=IFERROR(INDEX(商品管理!E:E,MATCH(B147,商品管理!A:A,0)),"")} | AE147: {=IFERROR(INDEX(商品管理!F:F,MATCH(B147,商品管理!A:A,0)),"")} | AF147: {=IFERROR(INDEX(FBA仓库代码表!G:G,MATCH(E147,FBA仓库代码表!B:B,0)),"")} | AG147: {=IFERROR(INDEX(FBA仓库代码表!H:H,MATCH(E147,FBA仓库代码表!B:B,0)),"")}
AD148: {=IFERROR(INDEX(商品管理!E:E,MATCH(B148,商品管理!A:A,0)),"")} | AE148: {=IFERROR(INDEX(商品管理!F:F,MATCH(B148,商品管理!A:A,0)),"")} | AF148: {=IFERROR(INDEX(FBA仓库代码表!G:G,MATCH(E148,FBA仓库代码表!B:B,0)),"")} | AG148: {=IFERROR(INDEX(FBA仓库代码表!H:H,MATCH(E148,FBA仓库代码表!B:B,0)),"")}
AD149: {=IFERROR(INDEX(商品管理!E:E,MATCH(B149,商品管理!A:A,0)),"")} | AE149: {=IFERROR(INDEX(商品管理!F:F,MATCH(B149,商品管理!A:A,0)),"")} | AF149: {=IFERROR(INDEX(FBA仓库代码表!G:G,MATCH(E149,FBA仓库代码表!B:B,0)),"")} | AG149: {=IFERROR(INDEX(FBA仓库代码表!H:H,MATCH(E149,FBA仓库代码表!B:B,0)),"")}
AD150: {=IFERROR(INDEX(商品管理!E:E,MATCH(B150,商品管理!A:A,0)),"")} | AE150: {=IFERROR(INDEX(商品管理!F:F,MATCH(B150,商品管理!A:A,0)),"")} | AF150: {=IFERROR(INDEX(FBA仓库代码表!G:G,MATCH(E150,FBA仓库代码表!B:B,0)),"")} | AG150: {=IFERROR(INDEX(FBA仓库代码表!H:H,MATCH(E150,FBA仓库代码表!B:B,0)),"")}
AD151: {=IFERROR(INDEX(商品管理!E:E,MATCH(B151,商品管理!A:A,0)),"")} | AE151: {=IFERROR(INDEX(商品管理!F:F,MATCH(B151,商品管理!A:A,0)),"")} | AF151: {=IFERROR(INDEX(FBA仓库代码表!G:G,MATCH(E151,FBA仓库代码表!B:B,0)),"")} | AG151: {=IFERROR(INDEX(FBA仓库代码表!H:H,MATCH(E151,FBA仓库代码表!B:B,0)),"")}
AD152: {=IFERROR(INDEX(商品管理!E:E,MATCH(B152,商品管理!A:A,0)),"")} | AE152: {=IFERROR(INDEX(商品管理!F:F,MATCH(B152,商品管理!A:A,0)),"")} | AF152: {=IFERROR(INDEX(FBA仓库代码表!G:G,MATCH(E152,FBA仓库代码表!B:B,0)),"")} | AG152: {=IFERROR(INDEX(FBA仓库代码表!H:H,MATCH(E152,FBA仓库代码表!B:B,0)),"")}
AD153: {=IFERROR(INDEX(商品管理!E:E,MATCH(B153,商品管理!A:A,0)),"")} | AE153: {=IFERROR(INDEX(商品管理!F:F,MATCH(B153,商品管理!A:A,0)),"")} | AF153: {=IFERROR(INDEX(FBA仓库代码表!G:G,MATCH(E153,FBA仓库代码表!B:B,0)),"")} | AG153: {=IFERROR(INDEX(FBA仓库代码表!H:H,MATCH(E153,FBA仓库代码表!B:B,0)),"")}
... AD301: {=IFERROR(INDEX(商品管理!E:E,MATCH(B301,商品管理!A:A,0)),"")} | AE301: {=IFERROR(INDEX(商品管理!F:F,MATCH(B301,商品管理!A:A,0)),"")} | AF301: {=IFERROR(INDEX(FBA仓库代码表!G:G,MATCH(E301,FBA仓库代码表!B:B,0)),"")} | AG301: {=IFERROR(INDEX(FBA仓库代码表!H:H,MATCH(E301,FBA仓库代码表!B:B,0)),"")}
AD302: {=IFERROR(INDEX(商品管理!E:E,MATCH(B302,商品管理!A:A,0)),"")} | AF302: {=IFERROR(INDEX(FBA仓库代码表!G:G,MATCH(E302,FBA仓库代码表!B:B,0)),"")}

Sheet 商品管理
A1: *商品货号 | B1: *商品名称 | C1: *商品编码 | D1: *规格型号 | E1: *申报计量单位 | F1: *法定计量单位 | G1: 第二计量单位 | H1: *销售订单商品sku | I1: *商品数量比 | J1: 单箱数量 | K1: 单个净重 | L1: 包装盒重量 | M1: 单箱净重 | N1: 单箱毛重 | O1: 单箱体积 | P1: 单价 | Q1: 长 | R1: 宽 | S1: 高 | T1: 境内货源地 | U1: 商品单位
A2: AV-CMB-Mini-White | B2: 化妆包 | C2: 4202920000 | D2: 3|2|化妆包|人造革+PVC|AV-CMB-Mini-White | E2: 007 | F2: 035 | G2: 007 | H2: AV-CMB-Mini-White | I2: 2 | M2: =J2*K2 -> #VALUE! | N2: =M2+J2*L2+1.5 -> #VALUE!
A3: AV-CMB-WS | B3: 化妆包 | C3: 4202920000 | D3: 3|2|化妆包|人造革+PVC|AV-CMB-WS | E3: 007 | F3: 035 | G3: 007 | H3: AV-CMB-WS | I3: 1 | J3: 42 | K3: 0.24 | L3: 0.1 | M3: =J3*K3 -> 10.08 | N3: =M3+J3*L3+1.5 -> 15.78 | P3: 16 | Q3: 53 | R3: 47 | S3: 51
A4: Z6-Z0WQ-CRCK | B4: 化妆包 | C4: 4202920000 | D4: 3|2|化妆包|人造革+PVC|Z6-Z0WQ-CRCK | E4: 007 | F4: 035 | G4: 007 | H4: Z6-Z0WQ-CRCK | I4: 1 | J4: 24 | K4: 0.33 | L4: 0.1 | M4: =J4*K4 -> 7.92 | N4: =M4+J4*L4+1.5 -> 11.82 | P4: 26 | Q4: 53 | R4: 40 | S4: 56
A5: AV-CMB-DLW-M | B5: 化妆包 | C5: 4202920000 | D5: 3|2|化妆包|人造革+PVC|AV-CMB-DLW-M | E5: 007 | F5: 035 | G5: 007 | H5: AV-CMB-DLW-M | I5: 1 | M5: =J5*K5 -> #VALUE! | N5: =M5+J5*L5+1.5 -> #VALUE!
A6: AV-CMB-WS-Thin | B6: 化妆包 | C6: 4202920000 | D6: 3|2|化妆包|人造革+PVC|AV-CMB-WS-Thin | E6: 007 | F6: 035 | G6: 007 | H6: AV-CMB-WS-Thin | I6: 1 | J6: 84 | K6: 0.14 | L6: 0.6 | M6: =J6*K6 -> 11.76 | N6: =M6+J6*L6+1.5 -> 63.66 | P6: 18 | Q6: 53 | R6: 47 | S6: 51
A7: AV-CMB-LM-White | B7: 化妆包 | C7: 4202920000 | D7: 3|2|化妆包|人造革+PVC|AV-CMB-LM-White | E7: 006 | F7: 035 | G7: 007 | H7: AV-CMB-LM-White | I7: 2 | J7: 24 | K7: 0.57 | L7: 0.1 | M7: =J7*K7 -> 13.68 | N7: =M7+J7*L7+1.5 -> 17.58 | P7: 34 | Q7: 53 | R7: 40 | S7: 56
A8: AV-CMB-DLW1 | B8: 化妆包 | C8: 4202920000 | D8: 3|2|化妆包|人造革+PVC|AV-CMB-DLW1 | E8: 007 | F8: 035 | G8: 007 | H8: AV-CMB-DLW1 | I8: 1 | J8: 20 | K8: 0.45 | L8: 0.18 | M8: =J8*K8 -> 9 | N8: =M8+J8*L8+1.5 -> 14.1 | P8: 32.5 | Q8: 55.5 | R8: 43 | S8: 56.5
A9: AV-CMB-Mini-Pink-New | B9: 化妆包 | C9: 4202920000 | D9: 3|2|化妆包|人造革+PVC|AV-CMB-Mini-Pink-New | E9: 007 | F9: 035 | G9: 007 | H9: AV-CMB-Mini-Pink-New | I9: 1 | M9: =J9*K9 -> #VALUE! | N9: =M9+J9*L9+1.5 -> #VALUE!
A10: AV-CMB-PK | B10: 化妆包 | C10: 4202920000 | D10: 3|2|化妆包|人造革+PVC|AV-CMB-PK | E10: 007 | F10: 035 | G10: 007 | H10: AV-CMB-PK | I10: 1 | M10: =J10*K10 -> #VALUE! | N10: =M10+J10*L10+1.5 -> #VALUE!
A11: H9-6F0N-20M3 | B11: 化妆包 | C11: 4202920000 | D11: 3|2|化妆包|人造革+PVC|H9-6F0N-20M3 | E11: 007 | F11: 035 | G11: 007 | H11: H9-6F0N-20M3 | I11: 1 | M11: =J11*K11 -> #VALUE! | N11: =M11+J11*L11+1.5 -> #VALUE!
A12: AV-CMB-DLP-M | B12: 化妆包 | C12: 4202920000 | D12: 3|2|化妆包|人造革+PVC|AV-CMB-DLP-M | E12: 007 | F12: 035 | G12: 007 | H12: AV-CMB-DLP-M | I12: 1 | J12: 24 | K12: 0.39 | L12: 0.18 | M12: =J12*K12 -> 9.36 | N12: =M12+J12*L12+1.5 -> 15.18 | P12: 31.5 | Q12: 51 | R12: 57.5 | S12: 44
A13: AV-CMB-DLP | B13: 化妆包 | C13: 4202920000 | D13: 3|2|化妆包|人造革+PVC|AV-CMB-DLP | E13: 007 | F13: 035 | G13: 007 | H13: AV-CMB-DLP | I13: 1 | M13: =J13*K13 -> #VALUE! | N13: =M13+J13*L13+1.5 -> #VALUE!
A14: AV-CMB-Pink-Thin | B14: 化妆包 | C14: 4202920000 | D14: 3|2|化妆包|人造革+PVC|AV-CMB-Pink-Thin | E14: 007 | F14: 035 | G14: 007 | H14: AV-CMB-Pink-Thin | I14: 1 | M14: =J14*K14 -> #VALUE! | N14: =M14+J14*L14+1.5 -> #VALUE!
A15: AV-CMB-LM-Pink | B15: 化妆包 | C15: 4202920000 | D15: 3|2|化妆包|人造革+PVC|AV-CMB-LM-Pink | E15: 006 | F15: 035 | G15: 007 | H15: AV-CMB-LM-Pink | I15: 2 | J15: 24 | K15: 0.57 | L15: 0.1 | M15: =J15*K15 -> 13.68 | N15: =M15+J15*L15+1.5 -> 17.58 | P15: 36 | Q15: 53 | R15: 40 | S15: 56
A16: AV-CMB-Black-Mini | B16: 化妆包 | C16: 4202920000 | D16: 3|2|化妆包|人造革+PVC|AV-CMB-Black-Mini | E16: 007 | F16: 035 | G16: 007 | H16: AV-CMB-Black-Mini | I16: 1 | M16: =J16*K16 -> #VALUE! | N16: =M16+J16*L16+1.5 -> #VALUE!
A17: AV-CMB-Mini-Black-New | B17: 化妆包 | C17: 4202920000 | D17: 3|2|化妆包|人造革+PVC|AV-CMB-Mini-Black-New | E17: 007 | F17: 035 | G17: 007 | H17: AV-CMB-Mini-Black-New | I17: 1 | M17: =J17*K17 -> #VALUE! | N17: =M17+J17*L17+1.5 -> #VALUE!
A18: P7-ERIK-PUBF | B18: 化妆包 | C18: 4202920000 | D18: 3|2|化妆包|人造革+PVC|P7-ERIK-PUBF | E18: 007 | F18: 035 | G18: 007 | H18: P7-ERIK-PUBF | I18: 1 | J18: 42 | K18: 0.24 | L18: 0 | M18: =J18*K18 -> 10.08 | N18: =M18+J18*L18+1.5 -> 11.58 | P18: 19 | Q18: 53 | R18: 47 | S18: 51
A19: F2-UBOI-C3KC | B19: 化妆包 | C19: 4202920000 | D19: 3|2|化妆包|人造革+PVC|F2-UBOI-C3KC | E19: 007 | F19: 035 | G19: 007 | H19: F2-UBOI-C3KC | I19: 1 | M19: =J19*K19 -> #VALUE! | N19: =M19+J19*L19+1.5 -> #VALUE!
A20: AV-CMB-DLBlack-M | B20: 化妆包 | C20: 4202920000 | D20: 3|2|化妆包|人造革+PVC|AV-CMB-DLBlack-M | E20: 007 | F20: 035 | G20: 007 | H20: AV-CMB-DLBlack-M | I20: 1 | M20: =J20*K20 -> #VALUE! | N20: =M20+J20*L20+1.5 -> #VALUE!
A21: AV-CMB-DLBlack | B21: 化妆包 | C21: 4202920000 | D21: 3|2|化妆包|人造革+PVC|AV-CMB-DLBlack | E21: 007 | F21: 035 | G21: 007 | H21: AV-CMB-DLBlack | I21: 1 | J21: 20 | K21: 0.45 | L21: 0.18 | M21: =J21*K21 -> 9 | N21: =M21+J21*L21+1.5 -> 14.1 | P21: 32.5 | Q21: 55.5 | R21: 43 | S21: 56.5
A22: AV-CMB-Black-Thin | B22: 化妆包 | C22: 4202920000 | D22: 3|2|化妆包|人造革+PVC|AV-CMB-Black-Thin | E22: 007 | F22: 035 | G22: 007 | H22: AV-CMB-Black-Thin | I22: 1 | J22: 84 | K22: 0.14 | L22: 0.6 | M22: =J22*K22 -> 11.76 | N22: =M22+J22*L22+1.5 -> 63.66 | P22: 18 | Q22: 53 | R22: 47 | S22: 51
A23: AV-CMB-LM-Black | B23: 化妆包 | C23: 4202920000 | D23: 3|2|化妆包|人造革+PVC|AV-CMB-LM-Black | E23: 006 | F23: 035 | G23: 007 | H23: AV-CMB-LM-Black | I23: 2 | M23: =J23*K23 -> #VALUE! | N23: =M23+J23*L23+1.5 -> #VALUE!
A24: AV-CMB-Blue-Mini | B24: 化妆包 | C24: 4202920000 | D24: 3|2|化妆包|人造革+PVC|AV-CMB-Blue-Mini | E24: 007 | F24: 035 | G24: 007 | H24: AV-CMB-Blue-Mini | I24: 1 | M24: =J24*K24 -> #VALUE! | N24: =M24+J24*L24+1.5 -> #VALUE!
A25: AV-CMB-Mini-Blue-Gray | B25: 化妆包 | C25: 4202920000 | D25: 3|2|化妆包|人造革+PVC|AV-CMB-Mini-Blue-Gray | E25: 007 | F25: 035 | G25: 007 | H25: AV-CMB-Mini-Blue-Gray | I25: 1 | M25: =J25*K25 -> #VALUE! | N25: =M25+J25*L25+1.5 -> #VALUE!
A26: AV-CMB-BlueM | B26: 化妆包 | C26: 4202920000 | D26: 3|2|化妆包|人造革+PVC|AV-CMB-BlueM | E26: 007 | F26: 035 | G26: 007 | H26: AV-CMB-BlueM | I26: 1 | M26: =J26*K26 -> #VALUE! | N26: =M26+J26*L26+1.5 -> #VALUE!
A27: AV-CMB-BlueL | B27: 化妆包 | C27: 4202920000 | D27: 3|2|化妆包|人造革+PVC|AV-CMB-BlueL | E27: 007 | F27: 035 | G27: 007 | H27: AV-CMB-BlueL | I27: 1 | M27: =J27*K27 -> #VALUE! | N27: =M27+J27*L27+1.5 -> #VALUE!
A28: AV-CMB-LM-Blue | B28: 化妆包 | C28: 4202920000 | D28: 3|2|化妆包|人造革+PVC|AV-CMB-LM-Blue | E28: 006 | F28: 035 | G28: 007 | H28: AV-CMB-LM-Blue | I28: 2 | J28: 24 | K28: 0.57 | L28: 0.1 | M28: =J28*K28 -> 13.68 | N28: =M28+J28*L28+1.5 -> 17.58 | P28: 36 | Q28: 53 | R28: 40 | S28: 56
A29: AV-CMB-Lilac-Mini | B29: 化妆包 | C29: 4202920000 | D29: 3|2|化妆包|人造革+PVC|AV-CMB-Lilac-Mini | E29: 007 | F29: 035 | G29: 007 | H29: AV-CMB-Lilac-Mini | I29: 1 | M29: =J29*K29 -> #VALUE! | N29: =M29+J29*L29+1.5 -> #VALUE!
A30: AV-CMB-LilacM | B30: 化妆包 | C30: 4202920000 | D30: 3|2|化妆包|人造革+PVC|AV-CMB-LilacM | E30: 007 | F30: 035 | G30: 007 | H30: AV-CMB-LilacM | I30: 1 | M30: =J30*K30 -> #VALUE! | N30: =M30+J30*L30+1.5 -> #VALUE!
A31: AV-CMB-LilacL | B31: 化妆包 | C31: 4202920000 | D31: 3|2|化妆包|人造革+PVC|AV-CMB-LilacL | E31: 007 | F31: 035 | G31: 007 | H31: AV-CMB-LilacL | I31: 1 | M31: =J31*K31 -> #VALUE! | N31: =M31+J31*L31+1.5 -> #VALUE!
A32: AV-CMB-D-Large-Lilac | B32: 化妆包 | C32: 4202920000 | D32: 3|2|化妆包|人造革+PVC|AV-CMB-D-Large-Lilac | E32: 007 | F32: 035 | G32: 007 | H32: AV-CMB-D-Large-Lilac | I32: 1 | J32: 20 | K32: 0.45 | L32: 0.18 | M32: =J32*K32 -> 9 | N32: =M32+J32*L32+1.5 -> 14.1 | P32: 32.5 | Q32: 55.5 | R32: 43 | S32: 56.5
A33: AV-CMB-PitayaPink-Mini | B33: 化妆包 | C33: 4202920000 | D33: 3|2|化妆包|人造革+PVC|AV-CMB-PitayaPink-Mini | E33: 007 | F33: 035 | G33: 007 | H33: AV-CMB-PitayaPink-Mini | I33: 1 | M33: =J33*K33 -> #VALUE! | N33: =M33+J33*L33+1.5 -> #VALUE!
A34: AV-CMB-PitayaPink-M | B34: 化妆包 | C34: 4202920000 | D34: 3|2|化妆包|人造革+PVC|AV-CMB-PitayaPink-M | E34: 007 | F34: 035 | G34: 007 | H34: AV-CMB-PitayaPink-M | I34: 1 | M34: =J34*K34 -> #VALUE! | N34: =M34+J34*L34+1.5 -> #VALUE!
A35: AV-CMB-PitayaPink-L | B35: 化妆包 | C35: 4202920000 | D35: 3|2|化妆包|人造革+PVC|AV-CMB-PitayaPink-L | E35: 007 | F35: 035 | G35: 007 | H35: AV-CMB-PitayaPink-L | I35: 1 | M35: =J35*K35 -> #VALUE! | N35: =M35+J35*L35+1.5 -> #VALUE!
A36: AV-CMB-DL-PitayaPink | B36: 化妆包 | C36: 4202920000 | D36: 3|2|化妆包|人造革+PVC|AV-CMB-DL-PitayaPink | E36: 007 | F36: 035 | G36: 007 | H36: AV-CMB-DL-PitayaPink | I36: 1 | M36: =J36*K36 -> #VALUE! | N36: =M36+J36*L36+1.5 -> #VALUE!
A37: AV-CMB-Mini-Taupe | B37: 化妆包 | C37: 4202920000 | D37: 3|2|化妆包|人造革+PVC|AV-CMB-Mini-Taupe | E37: 007 | F37: 035 | G37: 007 | H37: AV-CMB-Mini-Taupe | I37: 1 | M37: =J37*K37 -> #VALUE! | N37: =M37+J37*L37+1.5 -> #VALUE!
A38: AV-CMB-TaupeM | B38: 化妆包 | C38: 4202920000 | D38: 3|2|化妆包|人造革+PVC|AV-CMB-TaupeM | E38: 007 | F38: 035 | G38: 007 | H38: AV-CMB-TaupeM | I38: 1 | M38: =J38*K38 -> #VALUE! | N38: =M38+J38*L38+1.5 -> #VALUE!
A39: HQ-GXLM-GJBG | B39: 化妆包 | C39: 4202920000 | D39: 3|2|化妆包|人造革+PVC|HQ-GXLM-GJBG | E39: 007 | F39: 035 | G39: 007 | H39: HQ-GXLM-GJBG | I39: 1 | M39: =J39*K39 -> #VALUE! | N39: =M39+J39*L39+1.5 -> #VALUE!
A40: AV-CMB-DLW-Brown | B40: 化妆包 | C40: 4202920000 | D40: 3|2|化妆包|人造革+PVC|AV-CMB-DLW-Brown | E40: 007 | F40: 035 | G40: 007 | H40: AV-CMB-DLW-Brown | I40: 1 | M40: =J40*K40 -> #VALUE! | N40: =M40+J40*L40+1.5 -> #VALUE!
...

Sheet FBA仓库代码表
A1: 目的地 | B1: 仓库编码 | C1: 州省 | D1: 邮编 | E1: 地址 | F1: 完整地址 | G1: 国家编码 | H1: 货币编码 | I1: 目的港 | J1: country | K1: Destination
A2: 美国 | B2: SBD2 | C2: CA | D2: 92408 | E2: 1494 S Waterman Ave, San Bernardino | F2: =B2&"-"&E2&","&C2&D2&"- United States" -> SBD2-1494 S Waterman Ave, San Bernardino, CA92408- United States | G2: 502 | H2: 502 | I2: XXX | J2: USA | K2: =I2&" "&J2 -> XXX USA
A3: 美国 | B3: PSC2 | C3: WA | D3: 99301 | E3: 1351 S Road 40 E | F3: =B3&"-"&E3&","&C3&D3&"- United States" -> PSC2-1351 S Road 40 E,WA99301- United States | G3: 502 | H3: 502
A4: 美国 | B4: GEG2 | C4: WA | D4: 99216-6102 | E4: 18007 E Garland Ave | F4: =B4&"-"&E4&","&C4&D4&"- United States" -> GEG2-18007 E Garland Ave,WA99216-6102- United States | G4: 502 | H4: 502
A5: 美国 | B5: BFI1 | C5: WA | D5: 98390 | E5: 1800 140th Avenue E. | F5: =B5&"-"&E5&","&C5&D5&"- United States" -> BFI1-1800 140th Avenue E.,WA98390- United States | G5: 502 | H5: 502
A6: 美国 | B6: BFI7 | C6: WA | D6: 98390 | E6: 1901 140th Ave E | F6: =B6&"-"&E6&","&C6&D6&"- United States" -> BFI7-1901 140th Ave E,WA98390- United States | G6: 502 | H6: 502
A7: 美国 | B7: BFI3 | C7: WA | D7: 98327-9607 | E7: 2700 Center Drive | F7: =B7&"-"&E7&","&C7&D7&"- United States" -> BFI3-2700 Center Drive,WA98327-9607- United States | G7: 502 | H7: 502
A8: 美国 | B8: BFI9 | C8: WA | D8: 98327-7707 | E8: 3230 INTERNATIONAL PL, DUPONT | F8: =B8&"-"&E8&","&C8&D8&"- United States" -> BFI9-3230 INTERNATIONAL PL, DUPONT,WA98327-7707- United States | G8: 502 | H8: 502
A9: 美国 | B9: BFI4 | C9: WA | D9: 98032 | E9: 21005 64th Ave S | F9: =B9&"-"&E9&","&C9&D9&"- United States" -> BFI4-21005 64th Ave S,WA98032- United States | G9: 502 | H9: 502
A10: 美国 | B10: PDX7 | C10: OR | D10: 97317 | E10: 4775 Depot Ct SE | F10: =B10&"-"&E10&","&C10&D10&"- United States" -> PDX7-4775 Depot Ct SE,OR97317- United States | G10: 502 | H10: 502
A11: 美国 | B11: PSC2-UPS | C11: OR | D11: 97242 | E11: 9930 NE Alderwood Rd | F11: =B11&"-"&E11&","&C11&D11&"- United States" -> PSC2-UPS-9930 NE Alderwood Rd,OR97242- United States | G11: 502 | H11: 502
A12: 美国 | B12: PDX6 | C12: OR | D12: 97203 | E12: 15000 N. Lombard St | F12: =B12&"-"&E12&","&C12&D12&"- United States" -> PDX6-15000 N. Lombard St,OR97203- United States | G12: 502 | H12: 502
A13: 美国 | B13: SMF6 | C13: CA | D13: 95837-1109 | E13: 6900 AIRPORT BLVD City SACRAMENTO | F13: =B13&"-"&E13&","&C13&D13&"- United States" -> SMF6-6900 AIRPORT BLVD City SACRAMENTO ,CA 95837-1109- United States | G13: 502 | H13: 502
A14: 美国 | B14: SMF1 | C14: CA | D14: 95835-9505 | E14: 4900 W Elkhorn Blvd | F14: =B14&"-"&E14&","&C14&D14&"- United States" -> SMF1-4900 W Elkhorn Blvd,CA95835-9505- United States | G14: 502 | H14: 502
... A36: 美国 | B36: MIT2 | C36: CA | D36: 93263 | E36: 5408 Express Avenue | F36: =B36&"-"&E36&","&C36&D36&"- United States" -> MIT2-5408 Express Avenue,CA93263- United States | G36: 502 | H36: 502
A37: 美国 | B37: KRB4 | D37: 92571-9722 | E37: Finsterwalder Transport und Logistik GmbH , Schieferstrabe 16 | F37: =B37&"-"&E37&","&C37&D37&"- United States" -> KRB4-Finsterwalder Transport und Logistik GmbH , Schieferstrabe 16,92571-9722- United States | G37: 502 | H37: 502
A38: 美国 | B38: LGB9 | C38: CA | D38: 92571-7901 | E38: 4375 N Perris Blvd | F38: =B38&"-"&E38&","&C38&D38&"- United States" -> LGB9-4375 N Perris Blvd,CA92571-7901- United States | G38: 502 | H38: 502
A39: 美国 | B39: ONT6 | C39: CA | D39: 92551 | E39: 24208 San Michele Rd | F39: =B39&"-"&E39&","&C39&D39&"- United States" -> ONT6-24208 San Michele Rd,CA92551- United States | G39: 502 | H39: 502
A40: 美国 | B40: ONT8 | C40: CA | D40: 92551 | E40: 24300 Nandina Ave | F40: =B40&"-"&E40&","&C40&D40&"- United States" -> ONT8-24300 Nandina Ave,CA92551- United States | G40: 502 | H40: 502
A41: 美国 | B41: LGB6 | C41: CA | D41: 92518-1513 | E41: 20901 Krameria Ave | F41: =B41&"-"&E41&","&C41&D41&"- United States" -> LGB6-20901 Krameria Ave,CA92518-1513- United States | G41: 502 | H41: 502
A42: 美国 | B42: VGT2-UPS备用 | C42: CA | D42: 92518 | E42: 20701 Krameria Avenue | F42: =B42&"-"&E42&","&C42&D42&"- United States" -> VGT2-UPS备用-20701 Krameria Avenue,CA92518- United States | G42: 502 | H42: 502
A43: 美国 | B43: PSP3-UPS | C43: CA | D43: 92518 | E43: 20821 Krameria Avenue | F43: =B43&"-"&E43&","&C43&D43&"- United States" -> PSP3-UPS-20821 Krameria Avenue,CA92518- United States | G43: 502 | H43: 502
A44: 美国 | B44: POC3 | C44: CA | D44: 92509 | E44: 6120 Clinker Drive | F44: =B44&"-"&E44&","&C44&D44&"- United States" -> POC3-6120 Clinker Drive,CA92509- United States | G44: 502 | H44: 502
A45: 美国 | B45: POC3-UPS | C45: CA | D45: 92508 | E45: 6120 Clinker Dr | F45: =B45&"-"&E45&","&C45&D45&"- United States" -> POC3-UPS-6120 Clinker Dr,CA92508- United States | G45: 502 | H45: 502
A46: 美国 | B46: ONT5 | C46: CA | D46: 92408-2606 | E46: 2020 E Central Ave, San Bernardino | F46: =B46&"-"&E46&","&C46&D46&"- United States" -> ONT5-2020 E Central Ave, San Bernardino,CA92408-2606- United States | G46: 502 | H46: 502
A47: 美国 | B47: ONT2 | C47: CA | D47: 92408-0123 | E47: 1910 E central Ave | F47: =B47&"-"&E47&","&C47&D47&"- United States" -> ONT2-1910 E central Ave,CA92408-0123- United States | G47: 502 | H47: 502
A48: 美国 | B48: KRB1 | C48: CA | D48: 92408 | E48: 6001 Bethlehem Blvd | F48: =B48&"-"&E48&","&C48&D48&"- United States" -> KRB1-6001 Bethlehem Blvd,CA92408- United States | G48: 502 | H48: 502
A49: 美国 | B49: JOT1 | C49: CA | D49: 92408 | E49: 1494 S WATERMAN AVE | F49: =B49&"-"&E49&","&C49&D49&"- United States" -> JOT1-1494 S WATERMAN AVE,CA92408- United States | G49: 502 | H49: 502
A50: 美国 | B50: SBD3 | C50: CA | D50: 92407 | E50: 5990 Cajon Blvd | F50: =B50&"-"&E50&","&C50&D50&"- United States" -> SBD3-5990 Cajon Blvd,CA92407- United States | G50: 502 | H50: 502
A51: 美国 | B51: XLX7 | D51: 92394 | E51: 18580 Gateway Dr | F51: =B51&"-"&E51&","&C51&D51&"- United States" -> XLX7-18580 Gateway Dr,92394- United States | G51: 502 | H51: 502
A52: 美国 | B52: SNA4 | C52: CA | D52: 92376-3009 | E52: 2496 W Walnut Ave | F52: =B52&"-"&E52&","&C52&D52&"- United States" -> SNA4-2496 W Walnut Ave,CA92376-3009- United States | G52: 502 | H52: 502
A53: 美国 | B53: LGB7 | C53: CA | D53: 92376-2427 | E53: 1660 N. Linden Avenue | F53: =B53&"-"&E53&","&C53&D53&"- United States" -> LGB7-1660 N. Linden Avenue,CA92376-2427- United States | G53: 502 | H53: 502
A54: 美国 | B54: LGB8 | C54: CA | D54: 92376 | E54: 1568 N Linden Ave | F54: =B54&"-"&E54&","&C54&D54&"- United States" -> LGB8-1568 N Linden Ave,CA92376- United States | G54: 502 | H54: 502
A55: 美国 | B55: ONT9 | C55: CA | D55: 92374 | E55: 2125 W.San Bernandino Ave | F55: =B55&"-"&E55&","&C55&D55&"- United States" -> ONT9-2125 W.San Bernandino Ave,CA92374- United States | G55: 502 | H55: 502
A56: 美国 | B56: LGB4 | C56: CA | D56: 92374 | E56: 27517 Pioneer Avenue | F56: =B56&"-"&E56&","&C56&D56&"- United States" -> LGB4-27517 Pioneer Avenue,CA92374- United States | G56: 502 | H56: 502
A57: 美国 | B57: XLG1 | C57: CA | D57: 92374 | E57: 1901 California St | F57: =B57&"-"&E57&","&C57&D57&"- United States" -> XLG1-1901 California St,CA92374- United States | G57: 502 | H57: 502
A58: 美国 | B58: XON1 | C58: CA | D58: 92374 | E58: 2290 Palmetto Ave 92374 - Redlands | F58: =B58&"-"&E58&","&C58&D58&"- United States" -> XON1-2290 Palmetto Ave 92374 - Redlands,CA92374- United States | G58: 502 | H58: 502
A59: 美国 | B59: LAX9 | C59: CA | D59: 92337 | E59: 11263 Oleander Ave | F59: =B59&"-"&E59&","&C59&D59&"- United States" -> LAX9-11263 Oleander Ave,CA92337- United States | G59: 502 | H59: 502
A60: 美国 | B60: POC1 | C60: CA | D60: 92336-1123 | E60: 4121 LYTLE CREEK RD | F60: =B60&"-"&E60&","&C60&D60&"- United States" -> POC1-4121 LYTLE CREEK RD,CA92336-1123- United States | G60: 502 | H60: 502
A61: 美国 | B61: SBD1 | C61: CA | D61: 92316-3819 | E61: 3388 S Cactus Ave | F61: =B61&"-"&E61&","&C61&D61&"- United States" -> SBD1-3388 S Cactus Ave,CA92316-3819- United States | G61: 502 | H61: 502
...
